Workbook

Sheet Information
B3: Supplementary Data 1 | C3: SDT1 | D3: Information on samples studied in this work
B4: Supplementary Data 2 | C4: SDT2 | D4: La Palma clinopyroxene EMPA data and thermobarometery results
B5: Supplementary Data 3 | C5: SDT3 | D5: Clinopyroxene EMPA secondary standards
B6: Supplementary Data 4 | C6: SDT4 | D6: Clinopyroxene LA-ICP-MS single spot data
B7: Supplementary Data 5 | C7: SDT5 | D7: Clinopyroxene LA-ICP-MS single spot (SS) and maps standards
B8: Supplementary Data 6 | C8: SDT6 | D8: Matrix LA-ICP-MS major and trace element data
B9: Supplementary Data 7 | C9: SDT7 | D9: Matrix major elements LA-ICP-MS secondary standards
B10: Supplementary Data 8 | C10: SDT8 | D10: Matrix trace elements LA-ICP-MS secondary standards
B11: Supplementary Data 9 | C11: SDT9 | D11: Clinopyroxene EMPA data from the literature included as comparison data in this work
B12: Supplementary Data 10 | C12: SDT10 | D12: Melt (WR, matrix, glass) major and trace element data from the literature included as comparison data in this work
B13: Supplementary Data 11 | C13: SDT11 | D13: Clinopyroxene major element composition from OIBs worldwide.

Sheet Supplementary Data 1_Samples
A1: Supplementary Data 1. Studied samples from the 2021 Tajogaite, 1971 Teneguía and 1712 El Charco eruptions at Cumbre Vieja rift, La Palma, Canary Islands.
C3: UTM coordinates (28R)
A4: Sample | B4: Eruption | C4: Longitude (E) | D4: Latitude (N) | E4: Type | F4: Vent | G4: Days since eruption onset | H4: Date of eruption | I4: Date of sampling | J4: Rock type | K4: Reference for other work on the same sample
A5: IGME01 | B5: Tajogaite 2021 | C5: 218780 | D5: 3168483 | E5: Lava | F5: MainCone | G5: 0 | H5: 44458 | I5: 44458 | J5: Amphyble-bearing Tephrite | K5: Ubide et al. (2023)
A6: TQ2 | B6: Tajogaite 2021 | C6: 216025 | D6: 3169188 | E6: Lava | F6: MainCone | G6: 1 | H6: 44459 | I6: 44461 | J6: Amphyble-bearing Tephrite | K6: Ubide et al. (2023)
A7: TQ4 | B7: Tajogaite 2021 | C7: 217356 | D7: 3169318 | E7: Lava | F7: MainCone | G7: 1 | H7: 44459 | I7: 44461 | J7: Amphyble-bearing Tephrite | K7: Ubide et al. (2023)
A8: TQ8 | B8: Tajogaite 2021 | C8: 218031 | D8: 3168137 | E8: Lava | F8: MainCone | G8: 3 | H8: 44461 | I8: 44463 | J8: Amphyble-bearing Tephrite | K8: Ubide et al. (2023)
A9: TQ68 | B9: Tajogaite 2021 | C9: 218195 | D9: 3167592 | E9: lapilli | F9: MainCone | G9: 4 | H9: 44462 | I9: 44462 | J9: Amphyble-bearing Tephrite | K9: Ubide et al. (2023)
A10: TQ9 | B10: Tajogaite 2021 | C10: 216915 | D10: 3169340 | E10: Lava | F10: MainCone | G10: 6 | H10: 44464 | I10: 44464 | J10: Amphyble-bearing Tephrite | K10: Ubide et al. (2023)
A11: TQ17 | B11: Tajogaite 2021 | C11: 214168 | D11: 3168056 | E11: Lava | F11: MainCone | G11: 13 | H11: 44471 | I11: 44475 | J11: Olivine-bearing Basanite | K11: Ubide et al. (2023)
A12: TQ14 | B12: Tajogaite 2021 | C12: 217930 | D12: 3169220 | E12: Lava | F12: MainCone | G12: 14 | H12: 44472 | I12: 44474 | J12: Olivine-bearing Basanite | K12: Ubide et al. (2023)
A13: TQ16 | B13: Tajogaite 2021 | C13: 214636 | D13: 3168720 | E13: Lava | F13: MainCone | G13: 15 | H13: 44473 | I13: 44474 | J13: Olivine-bearing Basanite | K13: Ubide et al. (2023); Jegal et al. (2025)
A14: TQ29 | B14: Tajogaite 2021 | C14: 214079 | D14: 3169744 | E14: Lava | F14: MainCone | G14: 21 | H14: 44479 | I14: 44481 | J14: Olivine-bearing Basanite | K14: Ubide et al. (2023)
A15: TQ33 | B15: Tajogaite 2021 | C15: 216137 | D15: 3170362 | E15: Lava | F15: MainCone | G15: 25 | H15: 44483 | I15: 44484 | J15: Olivine-bearing Basanite | K15: Ubide et al. (2023)
A16: TQ38 | B16: Tajogaite 2021 | C16: 219162 | D16: 3169461 | E16: Lava | F16: MainCone | G16: 34 | H16: 44492 | I16: 44493 | J16: Olivine-bearing Basanite | K16: Ubide et al. (2023)
... A37: TQ66 | B37: Tajogaite 2021 | C37: 220029 | D37: 3168387 | E37: lapilli | F37: MainCone | G37: 85 | H37: 44543 | I37: 44544 | J37: Olivine-bearing Basanite | K37: Ubide et al. (2023)
A38: 43440 | B38: Teneguía 1971 | C38: 221519 | D38: 3151793 | E38: lava | G38: 3 | H38: 26234 | J38: Amphyble-bearing Tephrite
A39: 43136 | B39: Teneguía 1971 | C39: 221626 | D39: 3151848 | E39: lava | G39: 8 | H39: 26239 | J39: Amphyble-bearing Tephrite
A40: 43149 | B40: Teneguía 1971 | C40: 220256 | D40: 3152903 | E40: lava | G40: 22 | H40: 26253 | J40: Olivine-bearing Basanite
A41: 43154 | B41: Teneguía 1971 | C41: 221714 | D41: 3152007 | E41: lava | G41: 24 | H41: 26255 | J41: Olivine-bearing Basanite
A42: 63660 | B42: El Charco 1712 | C42: 219600 | D42: 3161625 | E42: lava | J42: Amphyble-bearing Tephrite
A43: 63664A | B43: El Charco 1712 | C43: 220800 | D43: 3162850 | E43: lava | J43: Amphyble-bearing Tephrite
A44: 63664B | B44: El Charco 1712 | C44: 220800 | D44: 3162850 | E44: lava | J44: Amphyble-bearing Tephrite
A45: 63661 | B45: El Charco 1712 | C45: 221000 | D45: 3161650 | E45: lava | J45: Olivine-bearing Basanite
A46: 63663 | B46: El Charco 1712 | C46: 219150 | D46: 3163450 | E46: lava | J46: Olivine-bearing Basanite
A47: 63671 | B47: El Charco 1712 | C47: 221150 | D47: 3161750 | E47: lava | J47: Olivine-bearing Basanite
A49: Samples from the 2021 Tajogaite, 1971 Teneguía and 1712 El Charco eruptions are curated at Litoteca de Petrologia at UCM and are available for sharing and collaborations upon request to Dr. A. Márquez

Sheet Supplementary Data 2_Cpx Empa
A1: Supplementary Data 2. Clinopyroxene EMPA major element composition from this work and from Ubide et al. (2023). An Helper column is avaiable both here and in SDT4 to match EMPA with LA-ICP-MS data on the same spot.
AO2: Thermodynamic-based cpx-liquid barometers | BI2: Machine-learning based cpx-only barometer
A3: Helper columns | C3: General information | L3: Cpx EMPA Data | Z3: EMPA uncertanties | AO3: P-T Masotta et al. (2013) | AT3: P-T Mollo et al. (2018) | AY3: P Putirka (2003), T Eq. 33 of Putirka (2008) | BD3: Preferred P-T estimated based on guidelines in MacDonald et al. (2023)
A4: EMPA_# | B4: LA-ICP-MS_# | C4: Sample | D4: ThinSection | E4: EMPA point | F4: Textural position | G4: Reference | H4: Eruption | I4: EruptionDate | J4: EmplacementDate | K4: Rock | L4: SiO2 | M4: TiO2 | N4: Al2O3 | O4: FeO | P4: MnO | Q4: MgO | R4: CaO | S4: Na2O | T4: K2O | U4: Cr2O3 | V4: Cr_EMPA | W4: NiO | X4: Total | Y4: Mg# | Z4: Si_err | AA4: Ti_err | AB4: Al_err | AC4: Fe_err | AD4: Mn_err | AE4: Mg_err | AF4: Ca_err | AG4: Na_err | AH4: K_err | AI4: Cr_err | AJ4: Ni_err | AK4: Mg#_err | AL4: Mg | AM4: Na | AN4: Fe2 + Mn | AO4: P_kbar_Masotta2013 (Palk2012) | AP4: P_kbar_Masotta2013_1σ | AQ4: T_°C_Masotta2013_Talk2012 | AR4: T_°C_Masotta2013_1σ | AS4: # of Liqs Averaged | AT4: P_kbar_Mollo2018 | AU4: P_kbar_Mollo2018_1σ | AV4: T_°C_Mollo2018 | AW4: T_°C_Mollo2018_1σ | AX4: # of Liqs Averaged | AY4: P_kbar_P2003(T33) | AZ4: P_kbar_P2003(T33)_1σ | BA4: T_°C_eq33_P2003 | BB4: T_°C_eq33_1σ | BC4: # of Liqs Averaged | BD4: P_Kbar_preferred | BE4: P_Kbar_1σ_preferred | BF4: T_°C_Preferred | BG4: T_°C__1σ_Preferred | BH4: # of Liqs Averaged | BI4: P (kbar) | BJ4: 16_Percentile - P (kbar) | BK4: 84_Percentile - P (kbar) | BL4: T (C) | BM4: 16_Percentile - T (C) | BN4: 84_Percentile - T (C)
A5: 1 | B5: 1 | C5: IG2611L2 | D5: 118508 | E5: 62 | F5: Core | G5: This work | H5: Tajogaite 2021 | I5: 44526 | J5: 44526 | K5: Basanite | L5: 50.132 | M5: 1.234 | N5: 3.701 | O5: 6.864 | P5: 0.223 | Q5: 13.661 | R5: 22.647 | S5: 0.833 | T5: 0.025 | U5: 0.076 | X5: 99.396 | Y5: 78.01089 | Z5: 0.43 | AA5: 4.98 | AB5: 1.71 | AC5: 1.45 | AD5: 15.32 | AE5: 0.6 | AF5: 0.59 | AG5: 3.44 | AH5: 48.41 | AI5: 34.33 | AJ5: 100 | AK5: 0.64365167 | AL5: 0.76309309 | AM5: 0.060509491 | AN5: 0.11662565 | BD5: =IF(OR($F5="Core",$F5="Cpx Inclusion"), IF($Y5<67, IF(AO5<>"",AO5,""), IF($Y5>67, IF(AY5<>"",AY5,""), "")), IF(OR($F5="Inner Rim",$F5="Outer Rim",$F5="Microlite"), IF(AT5<>"",AT5,""), IF($F5="Not Categorized","", ""))) | BE5: =IF(OR($F5="Core",$F5="Cpx Inclusion"), IF($Y5<67, IF(AP5<>"",AP5,""), IF($Y5>67, IF(AZ5<>"",AZ5,""), "")), IF(OR($F5="Inner Rim",$F5="Outer Rim",$F5="Microlite"), IF(AU5<>"",AU5,""), IF($F5="Not Categorized","", ""))) | BF5: =IF(OR($F5="Core",$F5="Cpx Inclusion"), IF($Y5<67, IF(AQ5<>"",AQ5,""), IF($Y5>67, IF(BA5<>"",BA5,""), "")), IF(OR($F5="Inner Rim",$F5="Outer Rim",$F5="Microlite"), IF(AV5<>"",AV5,""), IF($F5="Not Categorized","", ""))) | BG5: =IF(OR($F5="Core",$F5="Cpx Inclusion"), IF($Y5<67, IF(AR5<>"",AR5,""), IF($Y5>67, IF(BB5<>"",BB5,""), "")), IF(OR($F5="Inner Rim",$F5="Outer Rim",$F5="Microlite"), IF(AW5<>"",AW5,""), IF($F5="Not Categorized","", ""))) | BH5: =IF(OR($F5="Core",$F5="Cpx Inclusion"), IF($Y5<67, IF(AS5<>"",AS5,""), IF($Y5>67, IF(BC5<>"",BC5,""), "")), IF(OR($F5="Inner Rim",$F5="Outer Rim",$F5="Microlite"), IF(AX5<>"",AX5,""), IF($F5="Not Categorized","", ""))) | BI5: 5.3677098 | BJ5: 5.0652598 | BK5: 5.6989424 | BL5: 1049.2686 | BM5: 1037.8656 | BN5: 1059.3331
A6: 2 | B6: 2 | C6: IG2611L2 | D6: 118508 | E6: 63 | F6: Inner Rim | G6: This work | H6: Tajogaite 2021 | I6: 44526 | J6: 44526 | K6: Basanite | L6: 50.781 | M6: 0.797 | N6: 2.582 | O6: 6.786 | P6: 0.238 | Q6: 14.303 | R6: 22.607 | S6: 0.809 | T6: 0.012 | U6: 0.128 | X6: 99.043 | Y6: 78.9789 | Z6: 0.43 | AA6: 6.3 | AB6: 2.1 | AC6: 1.46 | AD6: 13.68 | AE6: 0.59 | AF6: 0.59 | AG6: 3.5 | AH6: 104.36 | AI6: 22.89 | AJ6: 100 | AK6: 0.64135307 | AL6: 0.80118432 | AM6: 0.058930116 | AN6: 0.099412983 | BD6: =IF(OR($F6="Core",$F6="Cpx Inclusion"), IF($Y6<67, IF(AO6<>"",AO6,""), IF($Y6>67, IF(AY6<>"",AY6,""), "")), IF(OR($F6="Inner Rim",$F6="Outer Rim",$F6="Microlite"), IF(AT6<>"",AT6,""), IF($F6="Not Categorized","", ""))) | BE6: =IF(OR($F6="Core",$F6="Cpx Inclusion"), IF($Y6<67, IF(AP6<>"",AP6,""), IF($Y6>67, IF(AZ6<>"",AZ6,""), "")), IF(OR($F6="Inner Rim",$F6="Outer Rim",$F6="Microlite"), IF(AU6<>"",AU6,""), IF($F6="Not Categorized","", ""))) | BF6: =IF(OR($F6="Core",$F6="Cpx Inclusion"), IF($Y6<67, IF(AQ6<>"",AQ6,""), IF($Y6>67, IF(BA6<>"",BA6,""), "")), IF(OR($F6="Inner Rim",$F6="Outer Rim",$F6="Microlite"), IF(AV6<>"",AV6,""), IF($F6="Not Categorized","", ""))) | BG6: =IF(OR($F6="Core",$F6="Cpx Inclusion"), IF($Y6<67, IF(AR6<>"",AR6,""), IF($Y6>67, IF(BB6<>"",BB6,""), "")), IF(OR($F6="Inner Rim",$F6="Outer Rim",$F6="Microlite"), IF(AW6<>"",AW6,""), IF($F6="Not Categorized","", ""))) | BH6: =IF(OR($F6="Core",$F6="Cpx Inclusion"), IF($Y6<67, IF(AS6<>"",AS6,""), IF($Y6>67, IF(BC6<>"",BC6,""), "")), IF(OR($F6="Inner Rim",$F6="Outer Rim",$F6="Microlite"), IF(AX6<>"",AX6,""), IF($F6="Not Categorized","", ""))) | BI6: 1.6092432 | BJ6: 1.4184873 | BK6: 1.8679676 | BL6: 1034.5948 | BM6: 1020.7295 | BN6: 1044.4638
A7: 2 | C7: TQ55 | D7: 118527 | E7: 52 | F7: Core | G7: This work | H7: Tajogaite 2021 | I7: 44525 | J7: 44525 | K7: Basanite | L7: 50.204 | M7: 1.262 | N7: 3.054 | O7: 6.274 | P7: 0.129 | Q7: 13.984 | R7: 23.435 | S7: 0.859 | T7: 0.015 | U7: 0.053 | W7: 0.034 | X7: 99.303 | Y7: 79.891809 | Z7: 0.42 | AA7: 4.8 | AB7: 1.89 | AC7: 2.3 | AD7: 30.9 | AE7: 0.59 | AF7: 0.58 | AG7: 3.5 | AH7: 78.9 | AI7: 49.07 | AJ7: 121.34 | AK7: 0.70747347 | AL7: 0.78217743 | AM7: 0.062481364 | AN7: 0.067959177 | BD7: =IF(OR($F7="Core",$F7="Cpx Inclusion"), IF($Y7<67, IF(AO7<>"",AO7,""), IF($Y7>67, IF(AY7<>"",AY7,""), "")), IF(OR($F7="Inner Rim",$F7="Outer Rim",$F7="Microlite"), IF(AT7<>"",AT7,""), IF($F7="Not Categorized","", ""))) | BE7: =IF(OR($F7="Core",$F7="Cpx Inclusion"), IF($Y7<67, IF(AP7<>"",AP7,""), IF($Y7>67, IF(AZ7<>"",AZ7,""), "")), IF(OR($F7="Inner Rim",$F7="Outer Rim",$F7="Microlite"), IF(AU7<>"",AU7,""), IF($F7="Not Categorized","", ""))) | BF7: =IF(OR($F7="Core",$F7="Cpx Inclusion"), IF($Y7<67, IF(AQ7<>"",AQ7,""), IF($Y7>67, IF(BA7<>"",BA7,""), "")), IF(OR($F7="Inner Rim",$F7="Outer Rim",$F7="Microlite"), IF(AV7<>"",AV7,""), IF($F7="Not Categorized","", ""))) | BG7: =IF(OR($F7="Core",$F7="Cpx Inclusion"), IF($Y7<67, IF(AR7<>"",AR7,""), IF($Y7>67, IF(BB7<>"",BB7,""), "")), IF(OR($F7="Inner Rim",$F7="Outer Rim",$F7="Microlite"), IF(AW7<>"",AW7,""), IF($F7="Not Categorized","", ""))) | BH7: =IF(OR($F7="Core",$F7="Cpx Inclusion"), IF($Y7<67, IF(AS7<>"",AS7,""), IF($Y7>67, IF(BC7<>"",BC7,""), "")), IF(OR($F7="Inner Rim",$F7="Outer Rim",$F7="Microlite"), IF(AX7<>"",AX7,""), IF($F7="Not Categorized","", ""))) | BI7: 1.9546705 | BJ7: 1.5357379 | BK7: 2.379043 | BL7: 1063.3611 | BM7: 1057.9916 | BN7: 1069.5108
A8: 3 | C8: TQ40 | D8: 118466 | E8: 85 | F8: Core | G8: This work | H8: Tajogaite 2021 | I8: 44493 | J8: 44493 | K8: Basanite | L8: 51.898 | M8: 1.003 | N8: 2.545 | O8: 6.004 | P8: 0.2 | Q8: 14.376 | R8: 23.116 | S8: 0.893 | U8: 0.007 | W8: 0.017 | X8: 100.059 | Y8: 81.018007 | Z8: 0.41 | AA8: 5.69 | AB8: 2.06 | AC8: 2.33 | AD8: 21.43 | AE8: 0.58 | AF8: 0.58 | AG8: 3.22 | AH8: 100 | AI8: 330.45 | AJ8: 229.73 | AK8: 0.70295644 | AL8: 0.79346343 | AM8: 0.064094945 | AN8: 0.1101073 | BD8: =IF(OR($F8="Core",$F8="Cpx Inclusion"), IF($Y8<67, IF(AO8<>"",AO8,""), IF($Y8>67, IF(AY8<>"",AY8,""), "")), IF(OR($F8="Inner Rim",$F8="Outer Rim",$F8="Microlite"), IF(AT8<>"",AT8,""), IF($F8="Not Categorized","", ""))) | BE8: =IF(OR($F8="Core",$F8="Cpx Inclusion"), IF($Y8<67, IF(AP8<>"",AP8,""), IF($Y8>67, IF(AZ8<>"",AZ8,""), "")), IF(OR($F8="Inner Rim",$F8="Outer Rim",$F8="Microlite"), IF(AU8<>"",AU8,""), IF($F8="Not Categorized","", ""))) | BF8: =IF(OR($F8="Core",$F8="Cpx Inclusion"), IF($Y8<67, IF(AQ8<>"",AQ8,""), IF($Y8>67, IF(BA8<>"",BA8,""), "")), IF(OR($F8="Inner Rim",$F8="Outer Rim",$F8="Microlite"), IF(AV8<>"",AV8,""), IF($F8="Not Categorized","", ""))) | BG8: =IF(OR($F8="Core",$F8="Cpx Inclusion"), IF($Y8<67, IF(AR8<>"",AR8,""), IF($Y8>67, IF(BB8<>"",BB8,""), "")), IF(OR($F8="Inner Rim",$F8="Outer Rim",$F8="Microlite"), IF(AW8<>"",AW8,""), IF($F8="Not Categorized","", ""))) | BH8: =IF(OR($F8="Core",$F8="Cpx Inclusion"), IF($Y8<67, IF(AS8<>"",AS8,""), IF($Y8>67, IF(BC8<>"",BC8,""), "")), IF(OR($F8="Inner Rim",$F8="Outer Rim",$F8="Microlite"), IF(AX8<>"",AX8,""), IF($F8="Not Categorized","", ""))) | BI8: 0.66354101 | BJ8: 0.57839117 | BK8: 0.81071563 | BL8: 1049.1392 | BM8: 1042.8364 | BN8: 1055.0715
A9: 4 | C9: TQ40 | D9: 118466 | E9: 89 | F9: Core | G9: This work | H9: Tajogaite 2021 | I9: 44493 | J9: 44493 | K9: Basanite | L9: 51.475 | M9: 0.992 | N9: 3.506 | O9: 6.728 | P9: 0.182 | Q9: 14.875 | R9: 22.208 | S9: 0.669 | T9: 0.007 | U9: 0.072 | W9: 0.055 | X9: 100.769 | Y9: 79.761439 | Z9: 0.41 | AA9: 5.81 | AB9: 1.74 | AC9: 2.19 | AD9: 23.77 | AE9: 0.57 | AF9: 0.59 | AG9: 3.89 | AH9: 183.02 | AI9: 35.6 | AJ9: 71.76 | AK9: 0.68057052 | AL9: 0.81566014 | AM9: 0.047704775 | AN9: 0.13309772 | BD9: =IF(OR($F9="Core",$F9="Cpx Inclusion"), IF($Y9<67, IF(AO9<>"",AO9,""), IF($Y9>67, IF(AY9<>"",AY9,""), "")), IF(OR($F9="Inner Rim",$F9="Outer Rim",$F9="Microlite"), IF(AT9<>"",AT9,""), IF($F9="Not Categorized","", ""))) | BE9: =IF(OR($F9="Core",$F9="Cpx Inclusion"), IF($Y9<67, IF(AP9<>"",AP9,""), IF($Y9>67, IF(AZ9<>"",AZ9,""), "")), IF(OR($F9="Inner Rim",$F9="Outer Rim",$F9="Microlite"), IF(AU9<>"",AU9,""), IF($F9="Not Categorized","", ""))) | BF9: =IF(OR($F9="Core",$F9="Cpx Inclusion"), IF($Y9<67, IF(AQ9<>"",AQ9,""), IF($Y9>67, IF(BA9<>"",BA9,""), "")), IF(OR($F9="Inner Rim",$F9="Outer Rim",$F9="Microlite"), IF(AV9<>"",AV9,""), IF($F9="Not Categorized","", ""))) | BG9: =IF(OR($F9="Core",$F9="Cpx Inclusion"), IF($Y9<67, IF(AR9<>"",AR9,""), IF($Y9>67, IF(BB9<>"",BB9,""), "")), IF(OR($F9="Inner Rim",$F9="Outer Rim",$F9="Microlite"), IF(AW9<>"",AW9,""), IF($F9="Not Categorized","", ""))) | BH9: =IF(OR($F9="Core",$F9="Cpx Inclusion"), IF($Y9<67, IF(AS9<>"",AS9,""), IF($Y9>67, IF(BC9<>"",BC9,""), "")), IF(OR($F9="Inner Rim",$F9="Outer Rim",$F9="Microlite"), IF(AX9<>"",AX9,""), IF($F9="Not Categorized","", ""))) | BI9: 4.8471908 | BJ9: 4.1887672 | BK9: 5.4851893 | BL9: 1058.4293 | BM9: 1054.1229 | BN9: 1065.1179
A10: 5 | C10: TQ40 | D10: 118466 | E10: 90 | F10: Core | G10: This work | H10: Tajogaite 2021 | I10: 44493 | J10: 44493 | K10: Basanite | L10: 52.049 | M10: 0.41 | N10: 2.02 | O10: 6.011 | P10: 0.178 | Q10: 14.626 | R10: 22.099 | S10: 0.696 | T10: 0.012 | U10: 0.081 | W10: 0.036 | X10: 98.218 | Y10: 81.263996 | Z10: 0.41 | AA10: 10.85 | AB10: 2.36 | AC10: 2.33 | AD10: 22.45 | AE10: 0.57 | AF10: 0.59 | AG10: 3.76 | AH10: 103.88 | AI10: 31.97 | AJ10: 110.67 | AK10: 0.69433678 | AL10: 0.81910514 | AM10: 0.050688191 | AN10: 0.15534474 | BD10: =IF(OR($F10="Core",$F10="Cpx Inclusion"), IF($Y10<67, IF(AO10<>"",AO10,""), IF($Y10>67, IF(AY10<>"",AY10,""), "")), IF(OR($F10="Inner Rim",$F10="Outer Rim",$F10="Microlite"), IF(AT10<>"",AT10,""), IF($F10="Not Categorized","", ""))) | BE10: =IF(OR($F10="Core",$F10="Cpx Inclusion"), IF($Y10<67, IF(AP10<>"",AP10,""), IF($Y10>67, IF(AZ10<>"",AZ10,""), "")), IF(OR($F10="Inner Rim",$F10="Outer Rim",$F10="Microlite"), IF(AU10<>"",AU10,""), IF($F10="Not Categorized","", ""))) | BF10: =IF(OR($F10="Core",$F10="Cpx Inclusion"), IF($Y10<67, IF(AQ10<>"",AQ10,""), IF($Y10>67, IF(BA10<>"",BA10,""), "")), IF(OR($F10="Inner Rim",$F10="Outer Rim",$F10="Microlite"), IF(AV10<>"",AV10,""), IF($F10="Not Categorized","", ""))) | BG10: =IF(OR($F10="Core",$F10="Cpx Inclusion"), IF($Y10<67, IF(AR10<>"",AR10,""), IF($Y10>67, IF(BB10<>"",BB10,""), "")), IF(OR($F10="Inner Rim",$F10="Outer Rim",$F10="Microlite"), IF(AW10<>"",AW10,""), IF($F10="Not Categorized","", ""))) | BH10: =IF(OR($F10="Core",$F10="Cpx Inclusion"), IF($Y10<67, IF(AS10<>"",AS10,""), IF($Y10>67, IF(BC10<>"",BC10,""), "")), IF(OR($F10="Inner Rim",$F10="Outer Rim",$F10="Microlite"), IF(AX10<>"",AX10,""), IF($F10="Not Categorized","", ""))) | BI10: 1.8945114 | BJ10: 1.6364186 | BK10: 2.2133021 | BL10: 1044.8253 | BM10: 1040.9081 | BN10: 1050.3062
A11: 6 | C11: TQ8 | D11: 118433 | E11: 151N | F11: Not Categorized | G11: This work | H11: Tajogaite 2021 | I11: 44461 | J11: 44461 | K11: Tephrite | L11: 50.4 | M11: 1.011 | N11: 3.288 | O11: 7.097 | P11: 0.212 | Q11: 14.277 | R11: 23.117 | S11: 0.777 | T11: 0.005 | W11: 0.006 | X11: 100.19 | Y11: 78.194278 | Z11: 0.43 | AA11: 5.44 | AB11: 1.88 | AC11: 2.16 | AD11: 19.84 | AE11: 0.6 | AF11: 0.6 | AG11: 3.76 | AH11: 232.75 | AI11: 100 | AJ11: 663.33 | AK11: 0.70024935 | AL11: 0.79294334 | AM11: 0.056118969 | AN11: 0.076785722 | BD11: =IF(OR($F11="Core",$F11="Cpx Inclusion"), IF($Y11<67, IF(AO11<>"",AO11,""), IF($Y11>67, IF(AY11<>"",AY11,""), "")), IF(OR($F11="Inner Rim",$F11="Outer Rim",$F11="Microlite"), IF(AT11<>"",AT11,""), IF($F11="Not Categorized","", ""))) | BE11: =IF(OR($F11="Core",$F11="Cpx Inclusion"), IF($Y11<67, IF(AP11<>"",AP11,""), IF($Y11>67, IF(AZ11<>"",AZ11,""), "")), IF(OR($F11="Inner Rim",$F11="Outer Rim",$F11="Microlite"), IF(AU11<>"",AU11,""), IF($F11="Not Categorized","", ""))) | BF11: =IF(OR($F11="Core",$F11="Cpx Inclusion"), IF($Y11<67, IF(AQ11<>"",AQ11,""), IF($Y11>67, IF(BA11<>"",BA11,""), "")), IF(OR($F11="Inner Rim",$F11="Outer Rim",$F11="Microlite"), IF(AV11<>"",AV11,""), IF($F11="Not Categorized","", ""))) | BG11: =IF(OR($F11="Core",$F11="Cpx Inclusion"), IF($Y11<67, IF(AR11<>"",AR11,""), IF($Y11>67, IF(BB11<>"",BB11,""), "")), IF(OR($F11="Inner Rim",$F11="Outer Rim",$F11="Microlite"), IF(AW11<>"",AW11,""), IF($F11="Not Categorized","", ""))) | BH11: =IF(OR($F11="Core",$F11="Cpx Inclusion"), IF($Y11<67, IF(AS11<>"",AS11,""), IF($Y11>67, IF(BC11<>"",BC11,""), "")), IF(OR($F11="Inner Rim",$F11="Outer Rim",$F11="Microlite"), IF(AX11<>"",AX11,""), IF($F11="Not Categorized","", ""))) | BI11: 1.4053941 | BJ11: 1.0735713 | BK11: 1.8638538 | BL11: 1049.7773 | BM11: 1040.3586 | BN11: 1056.0196
A12: 7 | C12: TQ55 | D12: 118527 | E12: 49 | F12: Core | G12: This work | H12: Tajogaite 2021 | I12: 44525 | J12: 44525 | K12: Basanite | L12: 45.916 | M12: 3.133 | N12: 6.435 | O12: 6.602 | P12: 0.062 | Q12: 12.564 | R12: 23.966 | S12: 0.827 | T12: 0.015 | X12: 99.52 | Y12: 77.232905 | Z12: 0.44 | AA12: 2.83 | AB12: 1.27 | AC12: 2.23 | AD12: 54.87 | AE12: 0.63 | AF12: 0.57 | AG12: 3.6 | AH12: 76.06 | AI12: 100 | AJ12: 100 | AK12: 0.72919413 | AL12: 0.70810571 | AM12: 0.060612074 | AN12: 0.023164968 | AT12: 5.0877712 | AU12: 0.51798212 | AV12: 1144.8876 | AW12: 15.950306 | AX12: 8 | BD12: =IF(OR($F12="Core",$F12="Cpx Inclusion"), IF($Y12<67, IF(AO12<>"",AO12,""), IF($Y12>67, IF(AY12<>"",AY12,""), "")), IF(OR($F12="Inner Rim",$F12="Outer Rim",$F12="Microlite"), IF(AT12<>"",AT12,""), IF($F12="Not Categorized","", ""))) | BE12: =IF(OR($F12="Core",$F12="Cpx Inclusion"), IF($Y12<67, IF(AP12<>"",AP12,""), IF($Y12>67, IF(AZ12<>"",AZ12,""), "")), IF(OR($F12="Inner Rim",$F12="Outer Rim",$F12="Microlite"), IF(AU12<>"",AU12,""), IF($F12="Not Categorized","", ""))) | BF12: =IF(OR($F12="Core",$F12="Cpx Inclusion"), IF($Y12<67, IF(AQ12<>"",AQ12,""), IF($Y12>67, IF(BA12<>"",BA12,""), "")), IF(OR($F12="Inner Rim",$F12="Outer Rim",$F12="Microlite"), IF(AV12<>"",AV12,""), IF($F12="Not Categorized","", ""))) | BG12: =IF(OR($F12="Core",$F12="Cpx Inclusion"), IF($Y12<67, IF(AR12<>"",AR12,""), IF($Y12>67, IF(BB12<>"",BB12,""), "")), IF(OR($F12="Inner Rim",$F12="Outer Rim",$F12="Microlite"), IF(AW12<>"",AW12,""), IF($F12="Not Categorized","", ""))) | BH12: =IF(OR($F12="Core",$F12="Cpx Inclusion"), IF($Y12<67, IF(AS12<>"",AS12,""), IF($Y12>67, IF(BC12<>"",BC12,""), "")), IF(OR($F12="Inner Rim",$F12="Outer Rim",$F12="Microlite"), IF(AX12<>"",AX12,""), IF($F12="Not Categorized","", ""))) | BI12: 10.34109 | BJ12: 8.9333752 | BK12: 11.348179 | BL12: 1170.551 | BM12: 1159.0227 | BN12: 1179.6237
A13: 8 | C13: TQ55 | D13: 118527 | E13: 50 | F13: Core | G13: This work | H13: Tajogaite 2021 | I13: 44525 | J13: 44525 | K13: Basanite | L13: 45.49 | M13: 2.832 | N13: 6.992 | O13: 6.265 | P13: 0.169 | Q13: 12.965 | R13: 22.951 | S13: 0.467 | U13: 0.038 | W13: 0.025 | X13: 98.194 | Y13: 78.672917 | Z13: 0.44 | AA13: 2.99 | AB13: 1.21 | AC13: 2.29 | AD13: 20.85 | AE13: 0.62 | AF13: 0.58 | AG13: 5.23 | AH13: 100 | AI13: 66.57 | AJ13: 163.68 | AK13: 0.72994336 | AL13: 0.73680791 | AM13: 0.034512952 | AN13: 0.071423261 | AT13: 5.8778844 | AU13: 0.66660421 | AV13: 1143.9673 | AW13: 15.064891 | AX13: 210 | AY13: 5.9441213 | AZ13: 0.61403725 | BA13: 1118.3925 | BB13: 16.265572 | BC13: 785 | BD13: =IF(OR($F13="Core",$F13="Cpx Inclusion"), IF($Y13<67, IF(AO13<>"",AO13,""), IF($Y13>67, IF(AY13<>"",AY13,""), "")), IF(OR($F13="Inner Rim",$F13="Outer Rim",$F13="Microlite"), IF(AT13<>"",AT13,""), IF($F13="Not Categorized","", ""))) -> 5.9441213 | BE13: =IF(OR($F13="Core",$F13="Cpx Inclusion"), IF($Y13<67, IF(AP13<>"",AP13,""), IF($Y13>67, IF(AZ13<>"",AZ13,""), "")), IF(OR($F13="Inner Rim",$F13="Outer Rim",$F13="Microlite"), IF(AU13<>"",AU13,""), IF($F13="Not Categorized","", ""))) -> 0.61403725 | BF13: =IF(OR($F13="Core",$F13="Cpx Inclusion"), IF($Y13<67, IF(AQ13<>"",AQ13,""), IF($Y13>67, IF(BA13<>"",BA13,""), "")), IF(OR($F13="Inner Rim",$F13="Outer Rim",$F13="Microlite"), IF(AV13<>"",AV13,""), IF($F13="Not Categorized","", ""))) -> 1118.3925 | BG13: =IF(OR($F13="Core",$F13="Cpx Inclusion"), IF($Y13<67, IF(AR13<>"",AR13,""), IF($Y13>67, IF(BB13<>"",BB13,""), "")), IF(OR($F13="Inner Rim",$F13="Outer Rim",$F13="Microlite"), IF(AW13<>"",AW13,""), IF($F13="Not Categorized","", ""))) -> 16.265572 | BH13: =IF(OR($F13="Core",$F13="Cpx Inclusion"), IF($Y13<67, IF(AS13<>"",AS13,""), IF($Y13>67, IF(BC13<>"",BC13,""), "")), IF(OR($F13="Inner Rim",$F13="Outer Rim",$F13="Microlite"), IF(AX13<>"",AX13,""), IF($F13="Not Categorized","", ""))) -> 785 | BI13: 0.9554218 | BJ13: 0.48044506 | BK13: 1.5796033 | BL13: 1118.4871 | BM13: 1106.785 | BN13: 1130.6698
A14: 9 | C14: TQ55 | D14: 118527 | E14: 51 | F14: Core | G14: This work | H14: Tajogaite 2021 | I14: 44525 | J14: 44525 | K14: Basanite | L14: 43.372 | M14: 4.423 | N14: 9.87 | O14: 6.396 | P14: 0.125 | Q14: 12.067 | R14: 23.864 | S14: 0.535 | T14: 0.016 | U14: 0.02 | W14: 0.017 | X14: 100.705 | Y14: 77.080249 | Z14: 0.45 | AA14: 2.35 | AB14: 1.01 | AC14: 2.26 | AD14: 31.95 | AE14: 0.64 | AF14: 0.57 | AG14: 4.68 | AH14: 69.1 | AI14: 126.16 | AJ14: 244.95 | AK14: 0.73983927 | AL14: 0.67290027 | AM14: 0.038796151 | AN14: 0.037967687 | BD14: =IF(OR($F14="Core",$F14="Cpx Inclusion"), IF($Y14<67, IF(AO14<>"",AO14,""), IF($Y14>67, IF(AY14<>"",AY14,""), "")), IF(OR($F14="Inner Rim",$F14="Outer Rim",$F14="Microlite"), IF(AT14<>"",AT14,""), IF($F14="Not Categorized","", ""))) | BE14: =IF(OR($F14="Core",$F14="Cpx Inclusion"), IF($Y14<67, IF(AP14<>"",AP14,""), IF($Y14>67, IF(AZ14<>"",AZ14,""), "")), IF(OR($F14="Inner Rim",$F14="Outer Rim",$F14="Microlite"), IF(AU14<>"",AU14,""), IF($F14="Not Categorized","", ""))) | BF14: =IF(OR($F14="Core",$F14="Cpx Inclusion"), IF($Y14<67, IF(AQ14<>"",AQ14,""), IF($Y14>67, IF(BA14<>"",BA14,""), "")), IF(OR($F14="Inner Rim",$F14="Outer Rim",$F14="Microlite"), IF(AV14<>"",AV14,""), IF($F14="Not Categorized","", ""))) | BG14: =IF(OR($F14="Core",$F14="Cpx Inclusion"), IF($Y14<67, IF(AR14<>"",AR14,""), IF($Y14>67, IF(BB14<>"",BB14,""), "")), IF(OR($F14="Inner Rim",$F14="Outer Rim",$F14="Microlite"), IF(AW14<>"",AW14,""), IF($F14="Not Categorized","", ""))) | BH14: =IF(OR($F14="Core",$F14="Cpx Inclusion"), IF($Y14<67, IF(AS14<>"",AS14,""), IF($Y14>67, IF(BC14<>"",BC14,""), "")), IF(OR($F14="Inner Rim",$F14="Outer Rim",$F14="Microlite"), IF(AX14<>"",AX14,""), IF($F14="Not Categorized","", ""))) | BI14: 0.92835217 | BJ14: 0.23063514 | BK14: 2.1995904 | BL14: 1134.3682 | BM14: 1125.3234 | BN14: 1143.251
A15: 10 | C15: TQ40 | D15: 118466 | E15: 87 | F15: Core | G15: This work | H15: Tajogaite 2021 | I15: 44493 | J15: 44493 | K15: Basanite | L15: 50.713 | M15: 1.053 | N15: 3.46 | O15: 7.911 | P15: 0.267 | Q15: 13.018 | R15: 22.917 | S15: 0.946 | U15: 0.03 | W15: 0.008 | X15: 100.323 | Y15: 74.576001 | Z15: 0.42 | AA15: 5.56 | AB15: 1.75 | AC15: 2 | AD15: 17.23 | AE15: 0.61 | AF15: 0.58 | AG15: 3.17 | AH15: 100 | AI15: 83.37 | AJ15: 502.22 | AK15: 0.68252509 | AL15: 0.72380297 | AM15: 0.068399149 | AN15: 0.14338424 | BD15: =IF(OR($F15="Core",$F15="Cpx Inclusion"), IF($Y15<67, IF(AO15<>"",AO15,""), IF($Y15>67, IF(AY15<>"",AY15,""), "")), IF(OR($F15="Inner Rim",$F15="Outer Rim",$F15="Microlite"), IF(AT15<>"",AT15,""), IF($F15="Not Categorized","", ""))) | BE15: =IF(OR($F15="Core",$F15="Cpx Inclusion"), IF($Y15<67, IF(AP15<>"",AP15,""), IF($Y15>67, IF(AZ15<>"",AZ15,""), "")), IF(OR($F15="Inner Rim",$F15="Outer Rim",$F15="Microlite"), IF(AU15<>"",AU15,""), IF($F15="Not Categorized","", ""))) | BF15: =IF(OR($F15="Core",$F15="Cpx Inclusion"), IF($Y15<67, IF(AQ15<>"",AQ15,""), IF($Y15>67, IF(BA15<>"",BA15,""), "")), IF(OR($F15="Inner Rim",$F15="Outer Rim",$F15="Microlite"), IF(AV15<>"",AV15,""), IF($F15="Not Categorized","", ""))) | BG15: =IF(OR($F15="Core",$F15="Cpx Inclusion"), IF($Y15<67, IF(AR15<>"",AR15,""), IF($Y15>67, IF(BB15<>"",BB15,""), "")), IF(OR($F15="Inner Rim",$F15="Outer Rim",$F15="Microlite"), IF(AW15<>"",AW15,""), IF($F15="Not Categorized","", ""))) | BH15: =IF(OR($F15="Core",$F15="Cpx Inclusion"), IF($Y15<67, IF(AS15<>"",AS15,""), IF($Y15>67, IF(BC15<>"",BC15,""), "")), IF(OR($F15="Inner Rim",$F15="Outer Rim",$F15="Microlite"), IF(AX15<>"",AX15,""), IF($F15="Not Categorized","", ""))) | BI15: 4.3793088 | BJ15: 3.8392882 | BK15: 4.9440706 | BL15: 990.58447 | BM15: 962.22699 | BN15: 1019.2005
A16: 11 | C16: IGME L1 | D16: 118507 | E16: 10 | F16: Core | G16: This work | H16: Tajogaite 2021 | I16: 44528 | J16: 44528 | K16: Basanite | L16: 46.8 | M16: 2.584 | N16: 6.448 | O16: 6.243 | P16: 0.099 | Q16: 13.184 | R16: 23.271 | S16: 0.483 | T16: 0.008 | U16: 0.38 | W16: 0.061 | X16: 99.561 | Y16: 79.011015 | Z16: 0.44 | AA16: 3.15 | AB16: 1.26 | AC16: 2.31 | AD16: 39.02 | AE16: 0.61 | AF16: 0.58 | AG16: 5.09 | AH16: 148.4 | AI16: 9.42 | AJ16: 65.24 | AK16: 0.72391986 | AL16: 0.73844846 | AM16: 0.035180629 | AN16: 0.084306893 | AT16: 5.6229305 | AU16: 0.64835132 | AV16: 1144.7739 | AW16: 16.005577 | AX16: 131 | BD16: =IF(OR($F16="Core",$F16="Cpx Inclusion"), IF($Y16<67, IF(AO16<>"",AO16,""), IF($Y16>67, IF(AY16<>"",AY16,""), "")), IF(OR($F16="Inner Rim",$F16="Outer Rim",$F16="Microlite"), IF(AT16<>"",AT16,""), IF($F16="Not Categorized","", ""))) | BE16: =IF(OR($F16="Core",$F16="Cpx Inclusion"), IF($Y16<67, IF(AP16<>"",AP16,""), IF($Y16>67, IF(AZ16<>"",AZ16,""), "")), IF(OR($F16="Inner Rim",$F16="Outer Rim",$F16="Microlite"), IF(AU16<>"",AU16,""), IF($F16="Not Categorized","", ""))) | BF16: =IF(OR($F16="Core",$F16="Cpx Inclusion"), IF($Y16<67, IF(AQ16<>"",AQ16,""), IF($Y16>67, IF(BA16<>"",BA16,""), "")), IF(OR($F16="Inner Rim",$F16="Outer Rim",$F16="Microlite"), IF(AV16<>"",AV16,""), IF($F16="Not Categorized","", ""))) | BG16: =IF(OR($F16="Core",$F16="Cpx Inclusion"), IF($Y16<67, IF(AR16<>"",AR16,""), IF($Y16>67, IF(BB16<>"",BB16,""), "")), IF(OR($F16="Inner Rim",$F16="Outer Rim",$F16="Microlite"), IF(AW16<>"",AW16,""), IF($F16="Not Categorized","", ""))) | BH16: =IF(OR($F16="Core",$F16="Cpx Inclusion"), IF($Y16<67, IF(AS16<>"",AS16,""), IF($Y16>67, IF(BC16<>"",BC16,""), "")), IF(OR($F16="Inner Rim",$F16="Outer Rim",$F16="Microlite"), IF(AX16<>"",AX16,""), IF($F16="Not Categorized","", ""))) | BI16: 1.3774945 | BJ16: 0.81606705 | BK16: 2.1655394 | BL16: 1152.3586 | BM16: 1146.8607 | BN16: 1158.2835
A17: 12 | C17: IGME L1 | D17: 118507 | E17: 11 | F17: Core | G17: This work | H17: Tajogaite 2021 | I17: 44528 | J17: 44528 | K17: Basanite | L17: 47.541 | M17: 2.713 | N17: 5.011 | O17: 7.846 | P17: 0.055 | Q17: 13.07 | R17: 23.03 | S17: 0.417 | U17: 0.045 | W17: 0.022 | X17: 99.75 | Y17: 74.807316 | Z17: 0.43 | AA17: 3.08 | AB17: 1.45 | AC17: 2.03 | AD17: 69.6 | AE17: 0.62 | AF17: 0.58 | AG17: 5.71 | AH17: 100 | AI17: 54.37 | AJ17: 181.14 | AK17: 0.6941634 | AL17: 0.73415745 | AM17: 0.030460228 | AN17: 0.14220556 | BD17: =IF(OR($F17="Core",$F17="Cpx Inclusion"), IF($Y17<67, IF(AO17<>"",AO17,""), IF($Y17>67, IF(AY17<>"",AY17,""), "")), IF(OR($F17="Inner Rim",$F17="Outer Rim",$F17="Microlite"), IF(AT17<>"",AT17,""), IF($F17="Not Categorized","", ""))) | BE17: =IF(OR($F17="Core",$F17="Cpx Inclusion"), IF($Y17<67, IF(AP17<>"",AP17,""), IF($Y17>67, IF(AZ17<>"",AZ17,""), "")), IF(OR($F17="Inner Rim",$F17="Outer Rim",$F17="Microlite"), IF(AU17<>"",AU17,""), IF($F17="Not Categorized","", ""))) | BF17: =IF(OR($F17="Core",$F17="Cpx Inclusion"), IF($Y17<67, IF(AQ17<>"",AQ17,""), IF($Y17>67, IF(BA17<>"",BA17,""), "")), IF(OR($F17="Inner Rim",$F17="Outer Rim",$F17="Microlite"), IF(AV17<>"",AV17,""), IF($F17="Not Categorized","", ""))) | BG17: =IF(OR($F17="Core",$F17="Cpx Inclusion"), IF($Y17<67, IF(AR17<>"",AR17,""), IF($Y17>67, IF(BB17<>"",BB17,""), "")), IF(OR($F17="Inner Rim",$F17="Outer Rim",$F17="Microlite"), IF(AW17<>"",AW17,""), IF($F17="Not Categorized","", ""))) | BH17: =IF(OR($F17="Core",$F17="Cpx Inclusion"), IF($Y17<67, IF(AS17<>"",AS17,""), IF($Y17>67, IF(BC17<>"",BC17,""), "")), IF(OR($F17="Inner Rim",$F17="Outer Rim",$F17="Microlite"), IF(AX17<>"",AX17,""), IF($F17="Not Categorized","", ""))) | BI17: 0.62195896 | BJ17: 0.43221258 | BK17: 0.78068438 | BL17: 1085.0646 | BM17: 1081.5027 | BN17: 1088.3955
A18: 13 | C18: TQ51 | D18: 118523 | E18: 42 | F18: Core | G18: This work | H18: Tajogaite 2021 | I18: 44493 | J18: 44493 | K18: Basanite | L18: 47.556 | M18: 2.72 | N18: 6.115 | O18: 6.699 | P18: 0.119 | Q18: 12.788 | R18: 23.062 | S18: 1.01 | U18: 0.086 | X18: 100.155 | Y18: 77.287123 | Z18: 0.43 | AA18: 3.12 | AB18: 1.27 | AC18: 1.47 | AD18: 23.86 | AE18: 0.62 | AF18: 0.58 | AG18: 3.1 | AH18: 100 | AI18: 32.08 | AJ18: 100 | AK18: 0.65830321 | AL18: 0.71239173 | AM18: 0.073167984 | AN18: 0.070734979 | AT18: 6.0577034 | AU18: 0.51029002 | AV18: 1158.7323 | AW18: 17.174485 | AX18: 29 | BD18: =IF(OR($F18="Core",$F18="Cpx Inclusion"), IF($Y18<67, IF(AO18<>"",AO18,""), IF($Y18>67, IF(AY18<>"",AY18,""), "")), IF(OR($F18="Inner Rim",$F18="Outer Rim",$F18="Microlite"), IF(AT18<>"",AT18,""), IF($F18="Not Categorized","", ""))) | BE18: =IF(OR($F18="Core",$F18="Cpx Inclusion"), IF($Y18<67, IF(AP18<>"",AP18,""), IF($Y18>67, IF(AZ18<>"",AZ18,""), "")), IF(OR($F18="Inner Rim",$F18="Outer Rim",$F18="Microlite"), IF(AU18<>"",AU18,""), IF($F18="Not Categorized","", ""))) | BF18: =IF(OR($F18="Core",$F18="Cpx Inclusion"), IF($Y18<67, IF(AQ18<>"",AQ18,""), IF($Y18>67, IF(BA18<>"",BA18,""), "")), IF(OR($F18="Inner Rim",$F18="Outer Rim",$F18="Microlite"), IF(AV18<>"",AV18,""), IF($F18="Not Categorized","", ""))) | BG18: =IF(OR($F18="Core",$F18="Cpx Inclusion"), IF($Y18<67, IF(AR18<>"",AR18,""), IF($Y18>67, IF(BB18<>"",BB18,""), "")), IF(OR($F18="Inner Rim",$F18="Outer Rim",$F18="Microlite"), IF(AW18<>"",AW18,""), IF($F18="Not Categorized","", ""))) | BH18: =IF(OR($F18="Core",$F18="Cpx Inclusion"), IF($Y18<67, IF(AS18<>"",AS18,""), IF($Y18>67, IF(BC18<>"",BC18,""), "")), IF(OR($F18="Inner Rim",$F18="Outer Rim",$F18="Microlite"), IF(AX18<>"",AX18,""), IF($F18="Not Categorized","", ""))) | BI18: 10.463106 | BJ18: 9.8205365 | BK18: 10.94305 | BL18: 1136.5295 | BM18: 1122.5387 | BN18: 1147.2196
A19: 14 | C19: TQ40 | D19: 118466 | E19: 43 | F19: Core | G19: This work | H19: Tajogaite 2021 | I19: 44493 | J19: 44493 | K19: Basanite | L19: 46.669 | M19: 2.875 | N19: 6.761 | O19: 8.245 | P19: 0.259 | Q19: 11.602 | R19: 23.06 | S19: 0.827 | U19: 0.037 | W19: 0.05 | X19: 100.385 | Y19: 71.496404 | Z19: 0.44 | AA19: 3.11 | AB19: 1.22 | AC19: 1.97 | AD19: 17.6 | AE19: 0.65 | AF19: 0.58 | AG19: 3.5 | AH19: 100 | AI19: 69.17 | AJ19: 80.51 | AK19: 0.69824792 | AL19: 0.65034543 | AM19: 0.060283743 | AN19: 0.13485859 | AT19: 6.7996006 | AU19: 0.56380355 | AV19: 1141.7918 | AW19: 3.5423227 | AX19: 4 | AY19: 7.265217 | AZ19: 1.5834796 | BA19: 1107.6839 | BB19: 16.918277 | BC19: 10 | BD19: =IF(OR($F19="Core",$F19="Cpx Inclusion"), IF($Y19<67, IF(AO19<>"",AO19,""), IF($Y19>67, IF(AY19<>"",AY19,""), "")), IF(OR($F19="Inner Rim",$F19="Outer Rim",$F19="Microlite"), IF(AT19<>"",AT19,""), IF($F19="Not Categorized","", ""))) -> 7.265217 | BE19: =IF(OR($F19="Core",$F19="Cpx Inclusion"), IF($Y19<67, IF(AP19<>"",AP19,""), IF($Y19>67, IF(AZ19<>"",AZ19,""), "")), IF(OR($F19="Inner Rim",$F19="Outer Rim",$F19="Microlite"), IF(AU19<>"",AU19,""), IF($F19="Not Categorized","", ""))) -> 1.5834796 | BF19: =IF(OR($F19="Core",$F19="Cpx Inclusion"), IF($Y19<67, IF(AQ19<>"",AQ19,""), IF($Y19>67, IF(BA19<>"",BA19,""), "")), IF(OR($F19="Inner Rim",$F19="Outer Rim",$F19="Microlite"), IF(AV19<>"",AV19,""), IF($F19="Not Categorized","", ""))) -> 1107.6839 | BG19: =IF(OR($F19="Core",$F19="Cpx Inclusion"), IF($Y19<67, IF(AR19<>"",AR19,""), IF($Y19>67, IF(BB19<>"",BB19,""), "")), IF(OR($F19="Inner Rim",$F19="Outer Rim",$F19="Microlite"), IF(AW19<>"",AW19,""), IF($F19="Not Categorized","", ""))) -> 16.918277 | BH19: =IF(OR($F19="Core",$F19="Cpx Inclusion"), IF($Y19<67, IF(AS19<>"",AS19,""), IF($Y19>67, IF(BC19<>"",BC19,""), "")), IF(OR($F19="Inner Rim",$F19="Outer Rim",$F19="Microlite"), IF(AX19<>"",AX19,""), IF($F19="Not Categorized","", ""))) -> 10 | BI19: 8.2652025 | BJ19: 7.282467 | BK19: 9.184644 | BL19: 1089.673 | BM19: 1068.6919 | BN19: 1102.9945
A20: 15 | C20: TQ40 | D20: 118466 | E20: 61 | F20: Core | G20: This work | H20: Tajogaite 2021 | I20: 44493 | J20: 44493 | K20: Basanite | L20: 50.012 | M20: 1.879 | N20: 4.01 | O20: 6.258 | P20: 0.118 | Q20: 13.057 | R20: 23.578 | S20: 0.918 | T20: 0.004 | U20: 0.034 | X20: 99.868 | Y20: 78.809993 | Z20: 0.42 | AA20: 3.9 | AB20: 1.61 | AC20: 2.28 | AD20: 32.78 | AE20: 0.61 | AF20: 0.57 | AG20: 3.19 | AH20: 343.9 | AI20: 68.88 | AJ20: 100 | AK20: 0.72085612 | AL20: 0.72574214 | AM20: 0.066353692 | AN20: 0.11593799 | BD20: =IF(OR($F20="Core",$F20="Cpx Inclusion"), IF($Y20<67, IF(AO20<>"",AO20,""), IF($Y20>67, IF(AY20<>"",AY20,""), "")), IF(OR($F20="Inner Rim",$F20="Outer Rim",$F20="Microlite"), IF(AT20<>"",AT20,""), IF($F20="Not Categorized","", ""))) | BE20: =IF(OR($F20="Core",$F20="Cpx Inclusion"), IF($Y20<67, IF(AP20<>"",AP20,""), IF($Y20>67, IF(AZ20<>"",AZ20,""), "")), IF(OR($F20="Inner Rim",$F20="Outer Rim",$F20="Microlite"), IF(AU20<>"",AU20,""), IF($F20="Not Categorized","", ""))) | BF20: =IF(OR($F20="Core",$F20="Cpx Inclusion"), IF($Y20<67, IF(AQ20<>"",AQ20,""), IF($Y20>67, IF(BA20<>"",BA20,""), "")), IF(OR($F20="Inner Rim",$F20="Outer Rim",$F20="Microlite"), IF(AV20<>"",AV20,""), IF($F20="Not Categorized","", ""))) | BG20: =IF(OR($F20="Core",$F20="Cpx Inclusion"), IF($Y20<67, IF(AR20<>"",AR20,""), IF($Y20>67, IF(BB20<>"",BB20,""), "")), IF(OR($F20="Inner Rim",$F20="Outer Rim",$F20="Microlite"), IF(AW20<>"",AW20,""), IF($F20="Not Categorized","", ""))) | BH20: =IF(OR($F20="Core",$F20="Cpx Inclusion"), IF($Y20<67, IF(AS20<>"",AS20,""), IF($Y20>67, IF(BC20<>"",BC20,""), "")), IF(OR($F20="Inner Rim",$F20="Outer Rim",$F20="Microlite"), IF(AX20<>"",AX20,""), IF($F20="Not Categorized","", ""))) | BI20: 5.7947203 | BJ20: 5.3746607 | BK20: 6.1418176 | BL20: 1100.9258 | BM20: 1092.2933 | BN20: 1109.3067
A21: 16 | C21: TQ40 | D21: 118466 | E21: 69 | F21: Core | G21: This work | H21: Tajogaite 2021 | I21: 44493 | J21: 44493 | K21: Basanite | L21: 46.23 | M21: 2.889 | N21: 6.788 | O21: 8.012 | P21: 0.195 | Q21: 11.828 | R21: 22.818 | S21: 0.738 | U21: 0.107 | W21: 0.041 | X21: 99.646 | Y21: 72.463599 | Z21: 0.44 | AA21: 3.06 | AB21: 1.23 | AC21: 2 | AD21: 21.13 | AE21: 0.64 | AF21: 0.58 | AG21: 3.71 | AH21: 100 | AI21: 25.15 | AJ21: 98.21 | AK21: 0.69805787 | AL21: 0.66712687 | AM21: 0.054129865 | AN21: 0.12967159 | AT21: 6.4364177 | AU21: 0.87202555 | AV21: 1144.34 | AW21: 16.336547 | AX21: 21 | AY21: 7.2107124 | AZ21: 1.4081257 | BA21: 1113.3056 | BB21: 15.177923 | BC21: 23 | BD21: =IF(OR($F21="Core",$F21="Cpx Inclusion"), IF($Y21<67, IF(AO21<>"",AO21,""), IF($Y21>67, IF(AY21<>"",AY21,""), "")), IF(OR($F21="Inner Rim",$F21="Outer Rim",$F21="Microlite"), IF(AT21<>"",AT21,""), IF($F21="Not Categorized","", ""))) -> 7.2107124 | BE21: =IF(OR($F21="Core",$F21="Cpx Inclusion"), IF($Y21<67, IF(AP21<>"",AP21,""), IF($Y21>67, IF(AZ21<>"",AZ21,""), "")), IF(OR($F21="Inner Rim",$F21="Outer Rim",$F21="Microlite"), IF(AU21<>"",AU21,""), IF($F21="Not Categorized","", ""))) -> 1.4081257 | BF21: =IF(OR($F21="Core",$F21="Cpx Inclusion"), IF($Y21<67, IF(AQ21<>"",AQ21,""), IF($Y21>67, IF(BA21<>"",BA21,""), "")), IF(OR($F21="Inner Rim",$F21="Outer Rim",$F21="Microlite"), IF(AV21<>"",AV21,""), IF($F21="Not Categorized","", ""))) -> 1113.3056 | BG21: =IF(OR($F21="Core",$F21="Cpx Inclusion"), IF($Y21<67, IF(AR21<>"",AR21,""), IF($Y21>67, IF(BB21<>"",BB21,""), "")), IF(OR($F21="Inner Rim",$F21="Outer Rim",$F21="Microlite"), IF(AW21<>"",AW21,""), IF($F21="Not Categorized","", ""))) -> 15.177923 | BH21: =IF(OR($F21="Core",$F21="Cpx Inclusion"), IF($Y21<67, IF(AS21<>"",AS21,""), IF($Y21>67, IF(BC21<>"",BC21,""), "")), IF(OR($F21="Inner Rim",$F21="Outer Rim",$F21="Microlite"), IF(AX21<>"",AX21,""), IF($F21="Not Categorized","", ""))) -> 23 | BI21: 6.9215627 | BJ21: 4.9861516 | BK21: 7.9646443 | BL21: 1106.7029 | BM21: 1100.8376 | BN21: 1113.1702
A22: 17 | C22: TQ14 | D22: 118437 | E22: 93 | F22: Core | G22: This work | H22: Tajogaite 2021 | I22: 44472 | J22: 44472 | K22: Tephrite | L22: 46.312 | M22: 2.755 | N22: 7.37 | O22: 7.326 | P22: 0.147 | Q22: 12.696 | R22: 22.259 | S22: 0.743 | T22: 0.027 | U22: 0.039 | X22: 99.674 | Y22: 75.545183 | Z22: 0.44 | AA22: 2.9 | AB22: 1.14 | AC22: 2.08 | AD22: 31.43 | AE22: 0.63 | AF22: 0.59 | AG22: 3.97 | AH22: 5244.93 | AI22: 47.43 | AJ22: 100 | AK22: 0.70954406 | AL22: 0.71153659 | AM22: 0.054150517 | AN22: 0.098945905 | AT22: 7.0512569 | AU22: 0.57225593 | AV22: 1147.2358 | AW22: 12.055076 | AX22: 886 | AY22: 8.3964275 | AZ22: 0.74694789 | BA22: 1140.2612 | BB22: 13.768831 | BC22: 87 | BD22: =IF(OR($F22="Core",$F22="Cpx Inclusion"), IF($Y22<67, IF(AO22<>"",AO22,""), IF($Y22>67, IF(AY22<>"",AY22,""), "")), IF(OR($F22="Inner Rim",$F22="Outer Rim",$F22="Microlite"), IF(AT22<>"",AT22,""), IF($F22="Not Categorized","", ""))) -> 8.3964275 | BE22: =IF(OR($F22="Core",$F22="Cpx Inclusion"), IF($Y22<67, IF(AP22<>"",AP22,""), IF($Y22>67, IF(AZ22<>"",AZ22,""), "")), IF(OR($F22="Inner Rim",$F22="Outer Rim",$F22="Microlite"), IF(AU22<>"",AU22,""), IF($F22="Not Categorized","", ""))) -> 0.74694789 | BF22: =IF(OR($F22="Core",$F22="Cpx Inclusion"), IF($Y22<67, IF(AQ22<>"",AQ22,""), IF($Y22>67, IF(BA22<>"",BA22,""), "")), IF(OR($F22="Inner Rim",$F22="Outer Rim",$F22="Microlite"), IF(AV22<>"",AV22,""), IF($F22="Not Categorized","", ""))) -> 1140.2612 | BG22: =IF(OR($F22="Core",$F22="Cpx Inclusion"), IF($Y22<67, IF(AR22<>"",AR22,""), IF($Y22>67, IF(BB22<>"",BB22,""), "")), IF(OR($F22="Inner Rim",$F22="Outer Rim",$F22="Microlite"), IF(AW22<>"",AW22,""), IF($F22="Not Categorized","", ""))) -> 13.768831 | BH22: =IF(OR($F22="Core",$F22="Cpx Inclusion"), IF($Y22<67, IF(AS22<>"",AS22,""), IF($Y22>67, IF(BC22<>"",BC22,""), "")), IF(OR($F22="Inner Rim",$F22="Outer Rim",$F22="Microlite"), IF(AX22<>"",AX22,""), IF($F22="Not Categorized","", ""))) -> 87 | BI22: 9.1439772 | BJ22: 7.016181 | BK22: 10.70589 | BL22: 1121.0146 | BM22: 1110.3636 | BN22: 1134.559
A23: 18 | C23: TQ14 | D23: 118437 | E23: 94 | F23: Core | G23: This work | H23: Tajogaite 2021 | I23: 44472 | J23: 44472 | K23: Tephrite | L23: 45.963 | M23: 3.101 | N23: 7.639 | O23: 7.436 | P23: 0.135 | Q23: 12.399 | R23: 22.94 | S23: 0.697 | U23: 0.052 | X23: 100.362 | Y23: 74.825537 | Z23: 0.42 | AA23: 3.7 | AB23: 1.48 | AC23: 2.26 | AD23: 22.98 | AE23: 0.59 | AF23: 0.59 | AG23: 4.61 | AH23: 100 | AI23: 37.09 | AJ23: 134.91 | AK23: 0.69659903 | AL23: 0.69220159 | AM23: 0.050601359 | AN23: 0.093752582 | AT23: 6.799116 | AU23: 0.60266401 | AV23: 1153.8403 | AW23: 12.882462 | AX23: 310 | AY23: 7.8292487 | AZ23: 0.62696799 | BA23: 1129.7781 | BB23: 13.564438 | BC23: 156 | BD23: =IF(OR($F23="Core",$F23="Cpx Inclusion"), IF($Y23<67, IF(AO23<>"",AO23,""), IF($Y23>67, IF(AY23<>"",AY23,""), "")), IF(OR($F23="Inner Rim",$F23="Outer Rim",$F23="Microlite"), IF(AT23<>"",AT23,""), IF($F23="Not Categorized","", ""))) -> 7.8292487 | BE23: =IF(OR($F23="Core",$F23="Cpx Inclusion"), IF($Y23<67, IF(AP23<>"",AP23,""), IF($Y23>67, IF(AZ23<>"",AZ23,""), "")), IF(OR($F23="Inner Rim",$F23="Outer Rim",$F23="Microlite"), IF(AU23<>"",AU23,""), IF($F23="Not Categorized","", ""))) -> 0.62696799 | BF23: =IF(OR($F23="Core",$F23="Cpx Inclusion"), IF($Y23<67, IF(AQ23<>"",AQ23,""), IF($Y23>67, IF(BA23<>"",BA23,""), "")), IF(OR($F23="Inner Rim",$F23="Outer Rim",$F23="Microlite"), IF(AV23<>"",AV23,""), IF($F23="Not Categorized","", ""))) -> 1129.7781 | BG23: =IF(OR($F23="Core",$F23="Cpx Inclusion"), IF($Y23<67, IF(AR23<>"",AR23,""), IF($Y23>67, IF(BB23<>"",BB23,""), "")), IF(OR($F23="Inner Rim",$F23="Outer Rim",$F23="Microlite"), IF(AW23<>"",AW23,""), IF($F23="Not Categorized","", ""))) -> 13.564438 | BH23: =IF(OR($F23="Core",$F23="Cpx Inclusion"), IF($Y23<67, IF(AS23<>"",AS23,""), IF($Y23>67, IF(BC23<>"",BC23,""), "")), IF(OR($F23="Inner Rim",$F23="Outer Rim",$F23="Microlite"), IF(AX23<>"",AX23,""), IF($F23="Not Categorized","", ""))) -> 156 | BI23: 8.116643 | BJ23: 5.5269893 | BK23: 10.185488 | BL23: 1120.5625 | BM23: 1109.4992 | BN23: 1133.5059
A24: 19 | C24: TQ68 | D24: 118627 | E24: 140 | F24: Core | G24: This work | H24: Tajogaite 2021 | I24: 44462 | J24: 44462 | K24: Tephrite | L24: 42.997 | M24: 3.285 | N24: 9.672 | O24: 10.723 | P24: 0.346 | Q24: 8.725 | R24: 22.219 | S24: 0.925 | W24: 0.037 | X24: 98.929 | Y24: 59.190542 | Z24: 0.45 | AA24: 2.79 | AB24: 0.99 | AC24: 1.13 | AD24: 9.25 | AE24: 0.76 | AF24: 0.59 | AG24: 3.33 | AH24: 100 | AI24: 100 | AJ24: 97.61 | AK24: 0.58972654 | AL24: 0.50351047 | AM24: 0.069417388 | AN24: 0.19379033 | AO24: 5.7187369 | AP24: 0.14741347 | AQ24: 1012.7252 | AR24: 3.5425106 | AS24: 56 | AT24: 4.3165828 | AV24: 1123.1155 | AX24: 1 | AY24: 5.7364256 | AZ24: 1.7738649 | BA24: 1094.4946 | BB24: 18.507676 | BC24: 2 | BD24: =IF(OR($F24="Core",$F24="Cpx Inclusion"), IF($Y24<67, IF(AO24<>"",AO24,""), IF($Y24>67, IF(AY24<>"",AY24,""), "")), IF(OR($F24="Inner Rim",$F24="Outer Rim",$F24="Microlite"), IF(AT24<>"",AT24,""), IF($F24="Not Categorized","", ""))) -> 5.7187369 | BE24: =IF(OR($F24="Core",$F24="Cpx Inclusion"), IF($Y24<67, IF(AP24<>"",AP24,""), IF($Y24>67, IF(AZ24<>"",AZ24,""), "")), IF(OR($F24="Inner Rim",$F24="Outer Rim",$F24="Microlite"), IF(AU24<>"",AU24,""), IF($F24="Not Categorized","", ""))) -> 0.14741347 | BF24: =IF(OR($F24="Core",$F24="Cpx Inclusion"), IF($Y24<67, IF(AQ24<>"",AQ24,""), IF($Y24>67, IF(BA24<>"",BA24,""), "")), IF(OR($F24="Inner Rim",$F24="Outer Rim",$F24="Microlite"), IF(AV24<>"",AV24,""), IF($F24="Not Categorized","", ""))) -> 1012.7252 | BG24: =IF(OR($F24="Core",$F24="Cpx Inclusion"), IF($Y24<67, IF(AR24<>"",AR24,""), IF($Y24>67, IF(BB24<>"",BB24,""), "")), IF(OR($F24="Inner Rim",$F24="Outer Rim",$F24="Microlite"), IF(AW24<>"",AW24,""), IF($F24="Not Categorized","", ""))) -> 3.5425106 | BH24: =IF(OR($F24="Core",$F24="Cpx Inclusion"), IF($Y24<67, IF(AS24<>"",AS24,""), IF($Y24>67, IF(BC24<>"",BC24,""), "")), IF(OR($F24="Inner Rim",$F24="Outer Rim",$F24="Microlite"), IF(AX24<>"",AX24,""), IF($F24="Not Categorized","", ""))) -> 56 | BI24: 5.3272868 | BJ24: 4.323803 | BK24: 6.2491687 | BL24: 922.67918 | BM24: 909.0646 | BN24: 938.33555
A25: 20 | C25: TQ8 | D25: 118433 | E25: 152B | F25: Core | G25: This work | H25: Tajogaite 2021 | I25: 44461 | J25: 44461 | K25: Tephrite | L25: 44.254 | M25: 3.156 | N25: 8.598 | O25: 8.003 | P25: 0.237 | Q25: 11.759 | R25: 22.786 | S25: 0.949 | U25: 0.036 | W25: 0.066 | X25: 99.844 | Y25: 72.369182 | Z25: 0.46 | AA25: 2.88 | AB25: 1.14 | AC25: 2.02 | AD25: 18.8 | AE25: 0.67 | AF25: 0.6 | AG25: 3.33 | AH25: 100 | AI25: 73.4 | AJ25: 57.19 | AK25: 0.72207451 | AL25: 0.66465796 | AM25: 0.069755347 | AN25: 0.037595271 | BD25: =IF(OR($F25="Core",$F25="Cpx Inclusion"), IF($Y25<67, IF(AO25<>"",AO25,""), IF($Y25>67, IF(AY25<>"",AY25,""), "")), IF(OR($F25="Inner Rim",$F25="Outer Rim",$F25="Microlite"), IF(AT25<>"",AT25,""), IF($F25="Not Categorized","", ""))) | BE25: =IF(OR($F25="Core",$F25="Cpx Inclusion"), IF($Y25<67, IF(AP25<>"",AP25,""), IF($Y25>67, IF(AZ25<>"",AZ25,""), "")), IF(OR($F25="Inner Rim",$F25="Outer Rim",$F25="Microlite"), IF(AU25<>"",AU25,""), IF($F25="Not Categorized","", ""))) | BF25: =IF(OR($F25="Core",$F25="Cpx Inclusion"), IF($Y25<67, IF(AQ25<>"",AQ25,""), IF($Y25>67, IF(BA25<>"",BA25,""), "")), IF(OR($F25="Inner Rim",$F25="Outer Rim",$F25="Microlite"), IF(AV25<>"",AV25,""), IF($F25="Not Categorized","", ""))) | BG25: =IF(OR($F25="Core",$F25="Cpx Inclusion"), IF($Y25<67, IF(AR25<>"",AR25,""), IF($Y25>67, IF(BB25<>"",BB25,""), "")), IF(OR($F25="Inner Rim",$F25="Outer Rim",$F25="Microlite"), IF(AW25<>"",AW25,""), IF($F25="Not Categorized","", ""))) | BH25: =IF(OR($F25="Core",$F25="Cpx Inclusion"), IF($Y25<67, IF(AS25<>"",AS25,""), IF($Y25>67, IF(BC25<>"",BC25,""), "")), IF(OR($F25="Inner Rim",$F25="Outer Rim",$F25="Microlite"), IF(AX25<>"",AX25,""), IF($F25="Not Categorized","", ""))) | BI25: 11.651727 | BJ25: 10.492808 | BK25: 12.500165 | BL25: 1120.2402 | BM25: 1108.8369 | BN25: 1130.5906
A26: 21 | C26: TQ2 | E26: 31 | F26: Core | G26: This work | H26: Tajogaite 2021 | I26: 44459 | J26: 44460 | K26: Tephrite | L26: 44.662 | M26: 3.296 | N26: 8.604 | O26: 6.937 | P26: 0.18 | Q26: 12.812 | R26: 22.286 | S26: 0.67 | T26: 0.002 | U26: 0.269 | X26: 99.718 | Y26: 76.701981 | Z26: 0.42 | AA26: 3.6 | AB26: 1.49 | AC26: 2.24 | AD26: 39.11 | AE26: 0.58 | AF26: 0.58 | AG26: 5.1 | AH26: 325.72 | AI26: 74.97 | AJ26: 100 | AK26: 0.6888961 | AL26: 0.71900273 | AM26: 0.048895837 | AN26: 0.058082132 | BD26: =IF(OR($F26="Core",$F26="Cpx Inclusion"), IF($Y26<67, IF(AO26<>"",AO26,""), IF($Y26>67, IF(AY26<>"",AY26,""), "")), IF(OR($F26="Inner Rim",$F26="Outer Rim",$F26="Microlite"), IF(AT26<>"",AT26,""), IF($F26="Not Categorized","", ""))) | BE26: =IF(OR($F26="Core",$F26="Cpx Inclusion"), IF($Y26<67, IF(AP26<>"",AP26,""), IF($Y26>67, IF(AZ26<>"",AZ26,""), "")), IF(OR($F26="Inner Rim",$F26="Outer Rim",$F26="Microlite"), IF(AU26<>"",AU26,""), IF($F26="Not Categorized","", ""))) | BF26: =IF(OR($F26="Core",$F26="Cpx Inclusion"), IF($Y26<67, IF(AQ26<>"",AQ26,""), IF($Y26>67, IF(BA26<>"",BA26,""), "")), IF(OR($F26="Inner Rim",$F26="Outer Rim",$F26="Microlite"), IF(AV26<>"",AV26,""), IF($F26="Not Categorized","", ""))) | BG26: =IF(OR($F26="Core",$F26="Cpx Inclusion"), IF($Y26<67, IF(AR26<>"",AR26,""), IF($Y26>67, IF(BB26<>"",BB26,""), "")), IF(OR($F26="Inner Rim",$F26="Outer Rim",$F26="Microlite"), IF(AW26<>"",AW26,""), IF($F26="Not Categorized","", ""))) | BH26: =IF(OR($F26="Core",$F26="Cpx Inclusion"), IF($Y26<67, IF(AS26<>"",AS26,""), IF($Y26>67, IF(BC26<>"",BC26,""), "")), IF(OR($F26="Inner Rim",$F26="Outer Rim",$F26="Microlite"), IF(AX26<>"",AX26,""), IF($F26="Not Categorized","", ""))) | BI26: 6.8221415 | BJ26: 4.5772556 | BK26: 8.5732633 | BL26: 1129.5454 | BM26: 1120.4577 | BN26: 1139.2648
A27: 22 | C27: TQ2 | E27: 32 | F27: Core | G27: This work | H27: Tajogaite 2021 | I27: 44459 | J27: 44460 | K27: Tephrite | L27: 48.582 | M27: 2.137 | N27: 4.546 | O27: 6.14 | P27: 0.116 | Q27: 14.642 | R27: 22.789 | S27: 0.456 | T27: 0.004 | U27: 0.034 | X27: 99.446 | Y27: 80.955415 | Z27: 0.44 | AA27: 2.74 | AB27: 1.11 | AC27: 2.13 | AD27: 35.33 | AE27: 0.63 | AF27: 0.58 | AG27: 4.25 | AH27: 100 | AI27: 96.48 | AJ27: 100 | AK27: 0.73378726 | AL27: 0.81665657 | AM27: 0.033074049 | AN27: 0.080376079 | BD27: =IF(OR($F27="Core",$F27="Cpx Inclusion"), IF($Y27<67, IF(AO27<>"",AO27,""), IF($Y27>67, IF(AY27<>"",AY27,""), "")), IF(OR($F27="Inner Rim",$F27="Outer Rim",$F27="Microlite"), IF(AT27<>"",AT27,""), IF($F27="Not Categorized","", ""))) | BE27: =IF(OR($F27="Core",$F27="Cpx Inclusion"), IF($Y27<67, IF(AP27<>"",AP27,""), IF($Y27>67, IF(AZ27<>"",AZ27,""), "")), IF(OR($F27="Inner Rim",$F27="Outer Rim",$F27="Microlite"), IF(AU27<>"",AU27,""), IF($F27="Not Categorized","", ""))) | BF27: =IF(OR($F27="Core",$F27="Cpx Inclusion"), IF($Y27<67, IF(AQ27<>"",AQ27,""), IF($Y27>67, IF(BA27<>"",BA27,""), "")), IF(OR($F27="Inner Rim",$F27="Outer Rim",$F27="Microlite"), IF(AV27<>"",AV27,""), IF($F27="Not Categorized","", ""))) | BG27: =IF(OR($F27="Core",$F27="Cpx Inclusion"), IF($Y27<67, IF(AR27<>"",AR27,""), IF($Y27>67, IF(BB27<>"",BB27,""), "")), IF(OR($F27="Inner Rim",$F27="Outer Rim",$F27="Microlite"), IF(AW27<>"",AW27,""), IF($F27="Not Categorized","", ""))) | BH27: =IF(OR($F27="Core",$F27="Cpx Inclusion"), IF($Y27<67, IF(AS27<>"",AS27,""), IF($Y27>67, IF(BC27<>"",BC27,""), "")), IF(OR($F27="Inner Rim",$F27="Outer Rim",$F27="Microlite"), IF(AX27<>"",AX27,""), IF($F27="Not Categorized","", ""))) | BI27: 2.4677051 | BJ27: 2.036316 | BK27: 2.9098048 | BL27: 1086.7892 | BM27: 1080.8983 | BN27: 1093.5889
A28: 23 | C28: TQ2 | E28: 33 | F28: Core | G28: This work | H28: Tajogaite 2021 | I28: 44459 | J28: 44460 | K28: Tephrite | L28: 44.779 | M28: 3.539 | N28: 8.023 | O28: 6.801 | P28: 0.109 | Q28: 12.641 | R28: 22.277 | S28: 0.595 | U28: 0.026 | X28: 98.79 | Y28: 76.815495 | Z28: 0.48 | AA28: 1.99 | AB28: 0.86 | AC28: 1.63 | AD28: 26.27 | AE28: 0.65 | AF28: 0.79 | AG28: 1.77 | AH28: 2.89 | AI28: 184.93 | AJ28: 100 | AK28: 0.6933113 | AL28: 0.71491469 | AM28: 0.043759588 | AN28: 0.090965527 | BD28: =IF(OR($F28="Core",$F28="Cpx Inclusion"), IF($Y28<67, IF(AO28<>"",AO28,""), IF($Y28>67, IF(AY28<>"",AY28,""), "")), IF(OR($F28="Inner Rim",$F28="Outer Rim",$F28="Microlite"), IF(AT28<>"",AT28,""), IF($F28="Not Categorized","", ""))) | BE28: =IF(OR($F28="Core",$F28="Cpx Inclusion"), IF($Y28<67, IF(AP28<>"",AP28,""), IF($Y28>67, IF(AZ28<>"",AZ28,""), "")), IF(OR($F28="Inner Rim",$F28="Outer Rim",$F28="Microlite"), IF(AU28<>"",AU28,""), IF($F28="Not Categorized","", ""))) | BF28: =IF(OR($F28="Core",$F28="Cpx Inclusion"), IF($Y28<67, IF(AQ28<>"",AQ28,""), IF($Y28>67, IF(BA28<>"",BA28,""), "")), IF(OR($F28="Inner Rim",$F28="Outer Rim",$F28="Microlite"), IF(AV28<>"",AV28,""), IF($F28="Not Categorized","", ""))) | BG28: =IF(OR($F28="Core",$F28="Cpx Inclusion"), IF($Y28<67, IF(AR28<>"",AR28,""), IF($Y28>67, IF(BB28<>"",BB28,""), "")), IF(OR($F28="Inner Rim",$F28="Outer Rim",$F28="Microlite"), IF(AW28<>"",AW28,""), IF($F28="Not Categorized","", ""))) | BH28: =IF(OR($F28="Core",$F28="Cpx Inclusion"), IF($Y28<67, IF(AS28<>"",AS28,""), IF($Y28>67, IF(BC28<>"",BC28,""), "")), IF(OR($F28="Inner Rim",$F28="Outer Rim",$F28="Microlite"), IF(AX28<>"",AX28,""), IF($F28="Not Categorized","", ""))) | BI28: 3.8348736 | BJ28: 2.114829 | BK28: 6.0116551 | BL28: 1135.2944 | BM28: 1124.5764 | BN28: 1146.9389
A29: 24 | C29: IGME01 | D29: 118509 | E29: 138 | F29: Core | G29: This work | H29: Tajogaite 2021 | I29: 44458 | J29: 44458 | K29: Tephrite | L29: 45.583 | M29: 2.504 | N29: 9.068 | O29: 7.071 | P29: 0.114 | Q29: 12.185 | R29: 21.948 | S29: 0.733 | U29: 0.701 | W29: 0.041 | X29: 99.948 | Y29: 75.440586 | Z29: 0.46 | AA29: 2.92 | AB29: 1.1 | AC29: 1.42 | AD29: 22.78 | AE29: 0.65 | AF29: 0.59 | AG29: 4.18 | AH29: 100 | AI29: 19.29 | AJ29: 169.34 | AK29: 0.6682319 | AL29: 0.68039123 | AM29: 0.053225607 | AN29: 0.10929776 | AT29: 6.9521147 | AU29: 0.5898849 | AV29: 1144.3841 | AW29: 11.928228 | AX29: 919 | AY29: 9.2067747 | AZ29: 0.85690106 | BA29: 1167.7257 | BB29: 21.432673 | BC29: 928 | BD29: =IF(OR($F29="Core",$F29="Cpx Inclusion"), IF($Y29<67, IF(AO29<>"",AO29,""), IF($Y29>67, IF(AY29<>"",AY29,""), "")), IF(OR($F29="Inner Rim",$F29="Outer Rim",$F29="Microlite"), IF(AT29<>"",AT29,""), IF($F29="Not Categorized","", ""))) -> 9.2067747 | BE29: =IF(OR($F29="Core",$F29="Cpx Inclusion"), IF($Y29<67, IF(AP29<>"",AP29,""), IF($Y29>67, IF(AZ29<>"",AZ29,""), "")), IF(OR($F29="Inner Rim",$F29="Outer Rim",$F29="Microlite"), IF(AU29<>"",AU29,""), IF($F29="Not Categorized","", ""))) -> 0.85690106 | BF29: =IF(OR($F29="Core",$F29="Cpx Inclusion"), IF($Y29<67, IF(AQ29<>"",AQ29,""), IF($Y29>67, IF(BA29<>"",BA29,""), "")), IF(OR($F29="Inner Rim",$F29="Outer Rim",$F29="Microlite"), IF(AV29<>"",AV29,""), IF($F29="Not Categorized","", ""))) -> 1167.7257 | BG29: =IF(OR($F29="Core",$F29="Cpx Inclusion"), IF($Y29<67, IF(AR29<>"",AR29,""), IF($Y29>67, IF(BB29<>"",BB29,""), "")), IF(OR($F29="Inner Rim",$F29="Outer Rim",$F29="Microlite"), IF(AW29<>"",AW29,""), IF($F29="Not Categorized","", ""))) -> 21.432673 | BH29: =IF(OR($F29="Core",$F29="Cpx Inclusion"), IF($Y29<67, IF(AS29<>"",AS29,""), IF($Y29>67, IF(BC29<>"",BC29,""), "")), IF(OR($F29="Inner Rim",$F29="Outer Rim",$F29="Microlite"), IF(AX29<>"",AX29,""), IF($F29="Not Categorized","", ""))) -> 928 | BI29: 11.817486 | BJ29: 10.146798 | BK29: 13.164605 | BL29: 1151.7629 | BM29: 1140.6059 | BN29: 1162.4206
A30: 25 | C30: IGME01 | D30: 118509 | E30: 139 | F30: Core | G30: This work | H30: Tajogaite 2021 | I30: 44458 | J30: 44458 | K30: Tephrite | L30: 45.299 | M30: 3.093 | N30: 8.582 | O30: 7.137 | P30: 0.132 | Q30: 11.863 | R30: 22.352 | S30: 0.641 | U30: 0.159 | W30: 0.021 | X30: 99.279 | Y30: 74.766136 | Z30: 0.48 | AA30: 2.15 | AB30: 0.98 | AC30: 1.38 | AD30: 22 | AE30: 0.7 | AF30: 0.6 | AG30: 4.57 | AH30: 140.28 | AI30: 100 | AJ30: 164.75 | AK30: 0.70343319 | AL30: 0.66762008 | AM30: 0.04691118 | AN30: 0.13139808 | AT30: 7.1066679 | AU30: 0.58245297 | AV30: 1149.0827 | AW30: 11.286916 | AX30: 899 | AY30: 8.0172685 | AZ30: 0.74959246 | BA30: 1145.372 | BB30: 18.929868 | BC30: 904 | BD30: =IF(OR($F30="Core",$F30="Cpx Inclusion"), IF($Y30<67, IF(AO30<>"",AO30,""), IF($Y30>67, IF(AY30<>"",AY30,""), "")), IF(OR($F30="Inner Rim",$F30="Outer Rim",$F30="Microlite"), IF(AT30<>"",AT30,""), IF($F30="Not Categorized","", ""))) -> 8.0172685 | BE30: =IF(OR($F30="Core",$F30="Cpx Inclusion"), IF($Y30<67, IF(AP30<>"",AP30,""), IF($Y30>67, IF(AZ30<>"",AZ30,""), "")), IF(OR($F30="Inner Rim",$F30="Outer Rim",$F30="Microlite"), IF(AU30<>"",AU30,""), IF($F30="Not Categorized","", ""))) -> 0.74959246 | BF30: =IF(OR($F30="Core",$F30="Cpx Inclusion"), IF($Y30<67, IF(AQ30<>"",AQ30,""), IF($Y30>67, IF(BA30<>"",BA30,""), "")), IF(OR($F30="Inner Rim",$F30="Outer Rim",$F30="Microlite"), IF(AV30<>"",AV30,""), IF($F30="Not Categorized","", ""))) -> 1145.372 | BG30: =IF(OR($F30="Core",$F30="Cpx Inclusion"), IF($Y30<67, IF(AR30<>"",AR30,""), IF($Y30>67, IF(BB30<>"",BB30,""), "")), IF(OR($F30="Inner Rim",$F30="Outer Rim",$F30="Microlite"), IF(AW30<>"",AW30,""), IF($F30="Not Categorized","", ""))) -> 18.929868 | BH30: =IF(OR($F30="Core",$F30="Cpx Inclusion"), IF($Y30<67, IF(AS30<>"",AS30,""), IF($Y30>67, IF(BC30<>"",BC30,""), "")), IF(OR($F30="Inner Rim",$F30="Outer Rim",$F30="Microlite"), IF(AX30<>"",AX30,""), IF($F30="Not Categorized","", ""))) -> 904 | BI30: 6.4921849 | BJ30: 3.7711639 | BK30: 9.3900468 | BL30: 1136.5433 | BM30: 1125.3689 | BN30: 1148.5922
A31: 26 | C31: TQ66 | D31: 118606 | E31: 10 | F31: Core | G31: This work | H31: Tajogaite 2021 | I31: 44543 | J31: 44543 | K31: Basanite | L31: 49.553 | M31: 1.256 | N31: 4.459 | O31: 10.129 | P31: 0.253 | Q31: 10.72 | R31: 22.754 | S31: 1.358 | U31: 0.045 | X31: 100.527 | Y31: 65.356685 | Z31: 0.42 | AA31: 4.78 | AB31: 1.49 | AC31: 1.75 | AD31: 17.73 | AE31: 0.69 | AF31: 0.59 | AG31: 2.62 | AH31: 100 | AI31: 58.88 | AJ31: 100 | AK31: 0.66875939 | AL31: 0.60198034 | AM31: 0.099167819 | AN31: 0.18150199 | AO31: 4.9824514 | AP31: 0.13042416 | AQ31: 1008.4098 | AR31: 4.2165504 | AS31: 998 | BD31: =IF(OR($F31="Core",$F31="Cpx Inclusion"), IF($Y31<67, IF(AO31<>"",AO31,""), IF($Y31>67, IF(AY31<>"",AY31,""), "")), IF(OR($F31="Inner Rim",$F31="Outer Rim",$F31="Microlite"), IF(AT31<>"",AT31,""), IF($F31="Not Categorized","", ""))) -> 4.9824514 | BE31: =IF(OR($F31="Core",$F31="Cpx Inclusion"), IF($Y31<67, IF(AP31<>"",AP31,""), IF($Y31>67, IF(AZ31<>"",AZ31,""), "")), IF(OR($F31="Inner Rim",$F31="Outer Rim",$F31="Microlite"), IF(AU31<>"",AU31,""), IF($F31="Not Categorized","", ""))) -> 0.13042416 | BF31: =IF(OR($F31="Core",$F31="Cpx Inclusion"), IF($Y31<67, IF(AQ31<>"",AQ31,""), IF($Y31>67, IF(BA31<>"",BA31,""), "")), IF(OR($F31="Inner Rim",$F31="Outer Rim",$F31="Microlite"), IF(AV31<>"",AV31,""), IF($F31="Not Categorized","", ""))) -> 1008.4098 | BG31: =IF(OR($F31="Core",$F31="Cpx Inclusion"), IF($Y31<67, IF(AR31<>"",AR31,""), IF($Y31>67, IF(BB31<>"",BB31,""), "")), IF(OR($F31="Inner Rim",$F31="Outer Rim",$F31="Microlite"), IF(AW31<>"",AW31,""), IF($F31="Not Categorized","", ""))) -> 4.2165504 | BH31: =IF(OR($F31="Core",$F31="Cpx Inclusion"), IF($Y31<67, IF(AS31<>"",AS31,""), IF($Y31>67, IF(BC31<>"",BC31,""), "")), IF(OR($F31="Inner Rim",$F31="Outer Rim",$F31="Microlite"), IF(AX31<>"",AX31,""), IF($F31="Not Categorized","", ""))) -> 998 | BI31: 5.8580642 | BJ31: 5.4981748 | BK31: 6.2312624 | BL31: 1003.0765 | BM31: 987.21731 | BN31: 1014.8499
